<?xml version="1.0" encoding="utf-8"?>
<!-- This URDF was automatically created by SolidWorks to URDF Exporter! Originally created by Stephen Brawner (brawner@gmail.com) 
     Commit Version: 1.6.0-4-g7f85cfe  Build Version: 1.6.7995.38578
     For more information, please see http://wiki.ros.org/sw_urdf_exporter -->
<robot
  name="PONGBOT_W">
  <link
    name="BODY">
    <inertial>
      <origin
        xyz="-0.009766 -0.000477 0.00088"
        rpy="0 0 0" />
      <mass
        value="23.328" />
      <inertia
        ixx="0.19262"
        ixy="-0.002404"
        ixz="-0.000122"
        iyy="1.0817"
        iyz="-0.000142"
        izz="1.1999" />
    </inertial>
    <visual>
      <origin
        xyz="0 0 0"
        rpy="0 0 0" />
      <geometry>
        <mesh
          filename="package://PONGBOT_W/meshes/BODY.STL" />
      </geometry>
      <material
        name="">
        <color
          rgba="0.75294 0.75294 0.75294 1" />
      </material>
    </visual>
    <collision>
      <origin
        xyz="0 0 0"
        rpy="0 0 0" />
      <geometry>
        <mesh
          filename="package://PONGBOT_W/meshes/BODY.STL" />
      </geometry>
    </collision>
  </link>
  <link
    name="RL_HIP">
    <inertial>
      <origin
        xyz="-0.002897 -0.005227 -0.000725"
        rpy="0 0 0" />
      <mass
        value="1.5871" />
      <inertia
        ixx="0.00134"
        ixy="-1.4E-05"
        ixz="1.1E-05"
        iyy="0.001938"
        iyz="1E-06"
        izz="0.001584" />
    </inertial>
    <visual>
      <origin
        xyz="0 0 0"
        rpy="0 0 0" />
      <geometry>
        <mesh
          filename="package://PONGBOT_W/meshes/RL_HIP.STL" />
      </geometry>
      <material
        name="">
        <color
          rgba="0.75294 0.75294 0.75294 1" />
      </material>
    </visual>
    <collision>
      <origin
        xyz="0 0 0"
        rpy="0 0 0" />
      <geometry>
        <mesh
          filename="package://PONGBOT_W/meshes/RL_HIP.STL" />
      </geometry>
    </collision>
  </link>
  <joint
    name="RL_HR_JOINT"
    type="continuous">
    <origin
      xyz="-0.31804 0.1138 0"
      rpy="0 0 0" />
    <parent
      link="BODY" />
    <child
      link="RL_HIP" />
    <axis
      xyz="1 0 0" />
  </joint>
  <link
    name="RL_THIGH">
    <inertial>
      <origin
        xyz="0.000189 -0.010257 -0.038433"
        rpy="0 0 0" />
      <mass
        value="3.32" />
      <inertia
        ixx="0.028079"
        ixy="-2.3E-05"
        ixz="1.6E-05"
        iyy="0.028442"
        iyz="-0.001256"
        izz="0.003743" />
    </inertial>
    <visual>
      <origin
        xyz="0 0 0"
        rpy="0 0 0" />
      <geometry>
        <mesh
          filename="package://PONGBOT_W/meshes/RL_THIGH.STL" />
      </geometry>
      <material
        name="">
        <color
          rgba="0.75294 0.75294 0.75294 1" />
      </material>
    </visual>
    <collision>
      <origin
        xyz="0 0 0"
        rpy="0 0 0" />
      <geometry>
        <mesh
          filename="package://PONGBOT_W/meshes/RL_THIGH.STL" />
      </geometry>
    </collision>
  </link>
  <joint
    name="RL_HP_JOINT"
    type="continuous">
    <origin
      xyz="0 0.105 0"
      rpy="0 0 0" />
    <parent
      link="RL_HIP" />
    <child
      link="RL_THIGH" />
    <axis
      xyz="0 1 0" />
  </joint>
  <link
    name="RL_CALF">
    <inertial>
      <origin
        xyz="-0.035789 -0.007154 -0.234470"
        rpy="0 0 0" />
      <mass
        value="1.603349" />
      <inertia
        ixx="0.027448"
        ixy="0.000394"
        ixz="0.004712"
        iyy="0.028959"
        iyz="0.001677"
        izz="0.002580" />
    </inertial>
    <visual>
      <origin
        xyz="0 0 0"
        rpy="0 0 0" />
      <geometry>
        <mesh
          filename="package://PONGBOT_W/meshes/RL_CALF.STL" />
      </geometry>
      <material
        name="">
        <color
          rgba="0.75294 0.75294 0.75294 1" />
      </material>
    </visual>
    <collision>
      <origin
        xyz="0 0 0"
        rpy="0 0 0" />
      <geometry>
        <mesh
          filename="package://PONGBOT_W/meshes/RL_CALF.STL" />
      </geometry>
    </collision>
  </link>
  <joint
    name="RL_KN_JOINT"
    type="continuous">
    <origin
      xyz="0 0 -0.305"
      rpy="0 0 0" />
    <parent
      link="RL_THIGH" />
    <child
      link="RL_CALF" />
    <axis
      xyz="0 1 0" />
  </joint>
  <link
    name="RL_WHEEL">
    <inertial>
      <origin
        xyz="0 0.040126 0"
        rpy="0 0 0" />
      <mass
        value="1.01" />
      <inertia
        ixx="0.003696"
        ixy="0"
        ixz="0"
        iyy="0.007106"
        iyz="0"
        izz="0.003696" />
    </inertial>
    <visual>
      <origin
        xyz="0 0 0"
        rpy="0 0 0" />
      <geometry>
        <mesh
          filename="package://PONGBOT_W/meshes/RL_WHEEL.STL" />
      </geometry>
      <material
        name="">
        <color
          rgba="0.75294 0.75294 0.75294 1" />
      </material>
    </visual>
    <collision>
      <origin
        xyz="0 0 0"
        rpy="0 0 0" />
      <geometry>
        <mesh
          filename="package://PONGBOT_W/meshes/RL_WHEEL.STL" />
      </geometry>
    </collision>
  </link>
  <!--joint
    name="RL_WHEEL_JOINT"
    type="continuous"-->
  <joint
    name="RL_WHEEL_JOINT"
    type="fixed">
    <origin
      xyz="-0.032441 0 -0.32759"
      rpy="0 0 0" />
    <parent
      link="RL_CALF" />
    <child
      link="RL_WHEEL" />
    <!--axis
      xyz="0 1 0" /-->
    <axis
      xyz="0 0 0" />
  </joint>
  <link
    name="RR_HIP">
    <inertial>
      <origin
        xyz="-0.0028 0.005227 0.001089"
        rpy="0 0 0" />
      <mass
        value="1.5871" />
      <inertia
        ixx="0.001339"
        ixy="9E-06"
        ixz="-1E-05"
        iyy="0.001937"
        iyz="-1.5E-05"
        izz="0.001585" />
    </inertial>
    <visual>
      <origin
        xyz="0 0 0"
        rpy="0 0 0" />
      <geometry>
        <mesh
          filename="package://PONGBOT_W/meshes/RR_HIP.STL" />
      </geometry>
      <material
        name="">
        <color
          rgba="0.75294 0.75294 0.75294 1" />
      </material>
    </visual>
    <collision>
      <origin
        xyz="0 0 0"
        rpy="0 0 0" />
      <geometry>
        <mesh
          filename="package://PONGBOT_W/meshes/RR_HIP.STL" />
      </geometry>
    </collision>
  </link>
  <joint
    name="RR_HR_JOINT"
    type="continuous">
    <origin
      xyz="-0.31804 -0.1138 0"
      rpy="0 0 0" />
    <parent
      link="BODY" />
    <child
      link="RR_HIP" />
    <axis
      xyz="1 0 0" />
  </joint>
  <link
    name="RR_THIGH">
    <inertial>
      <origin
        xyz="-0.000189 0.010257 -0.038433"
        rpy="0 0 0" />
      <mass
        value="3.32" />
      <inertia
        ixx="0.028079"
        ixy="-2.3E-05"
        ixz="-1.6E-05"
        iyy="0.028442"
        iyz="0.001256"
        izz="0.003743" />
    </inertial>
    <visual>
      <origin
        xyz="0 0 0"
        rpy="0 0 0" />
      <geometry>
        <mesh
          filename="package://PONGBOT_W/meshes/RR_THIGH.STL" />
      </geometry>
      <material
        name="">
        <color
          rgba="0.75294 0.75294 0.75294 1" />
      </material>
    </visual>
    <collision>
      <origin
        xyz="0 0 0"
        rpy="0 0 0" />
      <geometry>
        <mesh
          filename="package://PONGBOT_W/meshes/RR_THIGH.STL" />
      </geometry>
    </collision>
  </link>
  <joint
    name="RR_HP_JOINT"
    type="continuous">
    <origin
      xyz="0 -0.105 0"
      rpy="0 0 0" />
    <parent
      link="RR_HIP" />
    <child
      link="RR_THIGH" />
    <axis
      xyz="0 1 0" />
  </joint>
  <link
    name="RR_CALF">
    <inertial>
      <origin
        xyz="-0.017892 0.0049092 -0.23698"
        rpy="0 0 0" />
      <mass
        value="1.603349" />
      <inertia
        ixx="0.027926"
        ixy="-0.000177"
        ixz="0.002307"
        iyy="0.028625"
        iyz="-0.001273"
        izz="0.001669" />
    </inertial>
    <visual>
      <origin
        xyz="0 0 0"
        rpy="0 0 0" />
      <geometry>
        <mesh
          filename="package://PONGBOT_W/meshes/RR_CALF.STL" />
      </geometry>
      <material
        name="">
        <color
          rgba="0.75294 0.75294 0.75294 1" />
      </material>
    </visual>
    <collision>
      <origin
        xyz="0 0 0"
        rpy="0 0 0" />
      <geometry>
        <mesh
          filename="package://PONGBOT_W/meshes/RR_CALF.STL" />
      </geometry>
    </collision>
  </link>
  <joint
    name="RR_KN_JOINT"
    type="continuous">
    <origin
      xyz="0 0 -0.305"
      rpy="0 0 0" />
    <parent
      link="RR_THIGH" />
    <child
      link="RR_CALF" />
    <axis
      xyz="0 1 0" />
  </joint>
  <link
    name="RR_WHEEL">
    <inertial>
      <origin
        xyz="0 -0.040126 0"
        rpy="0 0 0" />
      <mass
        value="1.01" />
      <inertia
        ixx="0.003696"
        ixy="0"
        ixz="0"
        iyy="0.007106"
        iyz="0"
        izz="0.003696" />
    </inertial>
    <visual>
      <origin
        xyz="0 0 0"
        rpy="0 0 0" />
      <geometry>
        <mesh
          filename="package://PONGBOT_W/meshes/RR_WHEEL.STL" />
      </geometry>
      <material
        name="">
        <color
          rgba="0.75294 0.75294 0.75294 1" />
      </material>
    </visual>
    <collision>
      <origin
        xyz="0 0 0"
        rpy="0 0 0" />
      <geometry>
        <mesh
          filename="package://PONGBOT_W/meshes/RR_WHEEL.STL" />
      </geometry>
    </collision>
  </link>
  <!--joint
    name="RR_WHEEL_JOINT"
    type="continuous"-->
  <joint
    name="RR_WHEEL_JOINT"
    type="fixed">
    <origin
      xyz="-0.032441 0 -0.32759"
      rpy="0 0 0" />
    <parent
      link="RR_CALF" />
    <child
      link="RR_WHEEL" />
    <!--axis
      xyz="0 1 0" /-->
    <axis
      xyz="0 0 0" />
  </joint>
  <link
    name="FL_HIP">
    <inertial>
      <origin
        xyz="0.002803 -0.005227 0.001089"
        rpy="0 0 0" />
      <mass
        value="1.5871" />
      <inertia
        ixx="0.001339"
        ixy="9E-06"
        ixz="1E-05"
        iyy="0.001938"
        iyz="1.5E-05"
        izz="0.001585" />
    </inertial>
    <visual>
      <origin
        xyz="0 0 0"
        rpy="0 0 0" />
      <geometry>
        <mesh
          filename="package://PONGBOT_W/meshes/FL_HIP.STL" />
      </geometry>
      <material
        name="">
        <color
          rgba="0.75294 0.75294 0.75294 1" />
      </material>
    </visual>
    <collision>
      <origin
        xyz="0 0 0"
        rpy="0 0 0" />
      <geometry>
        <mesh
          filename="package://PONGBOT_W/meshes/FL_HIP.STL" />
      </geometry>
    </collision>
  </link>
  <joint
    name="FL_HR_JOINT"
    type="continuous">
    <origin
      xyz="0.31804 0.1138 0"
      rpy="0 0 0" />
    <parent
      link="BODY" />
    <child
      link="FL_HIP" />
    <axis
      xyz="1 0 0" />
  </joint>
  <link
    name="FL_THIGH">
    <inertial>
      <origin
        xyz="0.000189 -0.010257 -0.038433"
        rpy="0 0 0" />
      <mass
        value="3.32" />
      <inertia
        ixx="0.028079"
        ixy="-2.3E-05"
        ixz="1.6E-05"
        iyy="0.028442"
        iyz="-0.001256"
        izz="0.003743" />
    </inertial>
    <visual>
      <origin
        xyz="0 0 0"
        rpy="0 0 0" />
      <geometry>
        <mesh
          filename="package://PONGBOT_W/meshes/FL_THIGH.STL" />
      </geometry>
      <material
        name="">
        <color
          rgba="0.75294 0.75294 0.75294 1" />
      </material>
    </visual>
    <collision>
      <origin
        xyz="0 0 0"
        rpy="0 0 0" />
      <geometry>
        <mesh
          filename="package://PONGBOT_W/meshes/FL_THIGH.STL" />
      </geometry>
    </collision>
  </link>
  <joint
    name="FL_HP_JOINT"
    type="continuous">
    <origin
      xyz="0 0.105 0"
      rpy="0 0 0" />
    <parent
      link="FL_HIP" />
    <child
      link="FL_THIGH" />
    <axis
      xyz="0 1 0" />
  </joint>
  <link
    name="FL_CALF">
    <inertial>
      <origin
        xyz="-0.035789 -0.007154 -0.234470"
        rpy="0 0 0" />
      <mass
        value="1.603349" />
      <inertia
        ixx="0.027448"
        ixy="0.000394"
        ixz="0.004712"
        iyy="0.028959"
        iyz="0.001677"
        izz="0.002580" />
    </inertial>
    <visual>
      <origin
        xyz="0 0 0"
        rpy="0 0 0" />
      <geometry>
        <mesh
          filename="package://PONGBOT_W/meshes/FL_CALF.STL" />
      </geometry>
      <material
        name="">
        <color
          rgba="0.75294 0.75294 0.75294 1" />
      </material>
    </visual>
    <collision>
      <origin
        xyz="0 0 0"
        rpy="0 0 0" />
      <geometry>
        <mesh
          filename="package://PONGBOT_W/meshes/FL_CALF.STL" />
      </geometry>
    </collision>
  </link>
  <joint
    name="FL_KN_JOINT"
    type="continuous">
    <origin
      xyz="0 0 -0.305"
      rpy="0 0 0" />
    <parent
      link="FL_THIGH" />
    <child
      link="FL_CALF" />
    <axis
      xyz="0 1 0" />
  </joint>
  <link
    name="FL_WHEEL">
    <inertial>
      <origin
        xyz="0 0.040126 0"
        rpy="0 0 0" />
      <mass
        value="1.01" />
      <inertia
        ixx="0.003696"
        ixy="0"
        ixz="0"
        iyy="0.007106"
        iyz="0"
        izz="0.003696" />
    </inertial>
    <visual>
      <origin
        xyz="0 0 0"
        rpy="0 0 0" />
      <geometry>
        <mesh
          filename="package://PONGBOT_W/meshes/FL_WHEEL.STL" />
      </geometry>
      <material
        name="">
        <color
          rgba="0.75294 0.75294 0.75294 1" />
      </material>
    </visual>
    <collision>
      <origin
        xyz="0 0 0"
        rpy="0 0 0" />
      <geometry>
        <mesh
          filename="package://PONGBOT_W/meshes/FL_WHEEL.STL" />
      </geometry>
    </collision>
  </link>
  <!--joint
    name="FL_WHEEL_JOINT"
    type="continuous"-->
  <joint
    name="FL_WHEEL_JOINT"
    type="fixed">
    <origin
      xyz="-0.032441 0 -0.32759"
      rpy="0 0 0" />
    <parent
      link="FL_CALF" />
    <child
      link="FL_WHEEL" />
    <!--axis
      xyz="0 -1 0" /-->
    <axis
      xyz="0 0 0" />
  </joint>
  <link
    name="FR_HIP">
    <inertial>
      <origin
        xyz="0.002897 0.005227 -0.000725"
        rpy="0 0 0" />
      <mass
        value="1.5871" />
      <inertia
        ixx="0.00134"
        ixy="-1.4E-05"
        ixz="-1.1E-05"
        iyy="0.001938"
        iyz="-1E-06"
        izz="0.001584" />
    </inertial>
    <visual>
      <origin
        xyz="0 0 0"
        rpy="0 0 0" />
      <geometry>
        <mesh
          filename="package://PONGBOT_W/meshes/FR_HIP.STL" />
      </geometry>
      <material
        name="">
        <color
          rgba="0.75294 0.75294 0.75294 1" />
      </material>
    </visual>
    <collision>
      <origin
        xyz="0 0 0"
        rpy="0 0 0" />
      <geometry>
        <mesh
          filename="package://PONGBOT_W/meshes/FR_HIP.STL" />
      </geometry>
    </collision>
  </link>
  <joint
    name="FR_HR_JOINT"
    type="continuous">
    <origin
      xyz="0.31804 -0.1138 0"
      rpy="0 0 0" />
    <parent
      link="BODY" />
    <child
      link="FR_HIP" />
    <axis
      xyz="1 0 0" />
  </joint>
  <link
    name="FR_THIGH">
    <inertial>
      <origin
        xyz="-0.000189 0.010257 -0.038433"
        rpy="0 0 0" />
      <mass
        value="3.32" />
      <inertia
        ixx="0.028079"
        ixy="-2.3E-05"
        ixz="-1.6E-05"
        iyy="0.028442"
        iyz="0.001256"
        izz="0.003743" />
    </inertial>
    <visual>
      <origin
        xyz="0 0 0"
        rpy="0 0 0" />
      <geometry>
        <mesh
          filename="package://PONGBOT_W/meshes/FR_THIGH.STL" />
      </geometry>
      <material
        name="">
        <color
          rgba="0.75294 0.75294 0.75294 1" />
      </material>
    </visual>
    <collision>
      <origin
        xyz="0 0 0"
        rpy="0 0 0" />
      <geometry>
        <mesh
          filename="package://PONGBOT_W/meshes/FR_THIGH.STL" />
      </geometry>
    </collision>
  </link>
  <joint
    name="FR_HP_JOINT"
    type="continuous">
    <origin
      xyz="0 -0.105 0"
      rpy="0 0 0" />
    <parent
      link="FR_HIP" />
    <child
      link="FR_THIGH" />
    <axis
      xyz="0 1 0" />
  </joint>
  <link
    name="FR_CALF">
    <inertial>
      <origin
        xyz="-0.017892 0.004092 -0.236398"
        rpy="0 0 0" />
      <mass
        value="1.603349" />
      <inertia
        ixx="0.027926"
        ixy="-0.000177"
        ixz="0.002307"
        iyy="0.028625"
        iyz="-0.001273"
        izz="0.001669" />
    </inertial>
    <visual>
      <origin
        xyz="0 0 0"
        rpy="0 0 0" />
      <geometry>
        <mesh
          filename="package://PONGBOT_W/meshes/FR_CALF.STL" />
      </geometry>
      <material
        name="">
        <color
          rgba="0.75294 0.75294 0.75294 1" />
      </material>
    </visual>
    <collision>
      <origin
        xyz="0 0 0"
        rpy="0 0 0" />
      <geometry>
        <mesh
          filename="package://PONGBOT_W/meshes/FR_CALF.STL" />
      </geometry>
    </collision>
  </link>
  <joint
    name="FR_KN_JOINT"
    type="continuous">
    <origin
      xyz="0 0 -0.305"
      rpy="0 0 0" />
    <parent
      link="FR_THIGH" />
    <child
      link="FR_CALF" />
    <axis
      xyz="0 1 0" />
  </joint>
  <link
    name="FR_WHEEL">
    <inertial>
      <origin
        xyz="0 -0.040126 0"
        rpy="0 0 0" />
      <mass
        value="1.01" />
      <inertia
        ixx="0.003696"
        ixy="0"
        ixz="0"
        iyy="0.007106"
        iyz="0"
        izz="0.003696" />
    </inertial>
    <visual>
      <origin
        xyz="0 0 0"
        rpy="0 0 0" />
      <geometry>
        <mesh
          filename="package://PONGBOT_W/meshes/FR_WHEEL.STL" />
      </geometry>
      <material
        name="">
        <color
          rgba="0.75294 0.75294 0.75294 1" />
      </material>
    </visual>
    <collision>
      <origin
        xyz="0 0 0"
        rpy="0 0 0" />
      <geometry>
        <mesh
          filename="package://PONGBOT_W/meshes/FR_WHEEL.STL" />
      </geometry>
    </collision>
  </link>
  <!--joint
    name="FR_WHEEL_JOINT"
    type="continuous"-->
  <joint
    name="FR_WHEEL_JOINT"
    type="fixed">
    <origin
      xyz="-0.032441 0 -0.32759"
      rpy="0 0 0" />
    <parent
      link="FR_CALF" />
    <child
      link="FR_WHEEL" />
    <!--axis
      xyz="0 1 0" /-->
    <axis
      xyz="0 0 0" />
  </joint>
</robot>
