<?xml version="1.0" ?>
<sdf version='1.7'>
  <model name='PONGBOT_W'>
  
  <!--joint name="fixed to ground" type="fixed">
    <parent>world</parent>
    <child>BODY</child>
   </joint-->


    <link name='BODY'>
      <inertial>
        <pose>-0.009766 -0.000477 0.00088 0 -0 0</pose>
        <mass>23.328</mass>
        <inertia>
          <ixx>0.19262</ixx>
          <ixy>-0.002404</ixy>
          <ixz>-0.000122</ixz>
          <iyy>1.0817</iyy>
          <iyz>-0.000142</iyz>
          <izz>1.1999</izz>
        </inertia>
      </inertial>
      <!--collision name='BODY_collision'>
        <pose>0 0 0 0 -0 0</pose>
        <geometry>
          <mesh>
            <scale>1 1 1</scale>
            <uri>model://PONGBOT_W/meshes/BODY.STL</uri>
          </mesh>
        </geometry>
      </collision-->
      <visual name='BODY_visual'>
        <pose>0 0 0 0 -0 0</pose>
        <geometry>
          <mesh>
            <scale>1 1 1</scale>
            <uri>model://PONGBOT_W/meshes/BODY.STL</uri>
          </mesh>
        </geometry>
          <material>
          <ambient>0 0 0 1</ambient>
          <diffuse>1 1 1 1</diffuse>
          <emissive>0 0 0 0</emissive>
          <specular>0 0 0 0</specular>
        </material>
      </visual>
      <sensor name='IMU' type='imu'>
        <pose relative_to='BODY'>0 0 0 0 -0 0</pose>
        <imu>
          <angular_velocity>
            <x>
              <noise type='none'></noise>
            </x>
            <y>
              <noise type='none'></noise>
            </y>
            <z>
              <noise type='none'></noise>
            </z>
          </angular_velocity>
          <linear_acceleration>
            <x>
              <noise type='none'></noise>
            </x>
            <y>
              <noise type="none"></noise>
            </y>
            <z>
              <noise type='none'></noise>
            </z>
          </linear_acceleration>
        </imu>
        <always_on>1</always_on>
        <update_rate>1000</update_rate>
        <visualize>true</visualize>
      </sensor>
    </link>
    <joint name='FL_HR_JOINT' type='revolute'>
      <pose relative_to='BODY'>0.31804 0.1138 0 0 -0 0</pose>
      <parent>BODY</parent>
      <child>FL_HIP</child>
      <axis>
        <xyz>1 0 0</xyz>
        <limit>
          <lower>-1e+16</lower>
          <upper>1e+16</upper>
        </limit>
        <dynamics>
          <spring_reference>0</spring_reference>
          <spring_stiffness>0</spring_stiffness>
        </dynamics>
      </axis>
    </joint>
    <link name='FL_HIP'>
      <pose relative_to='FL_HR_JOINT'>0 0 0 0 -0 0</pose>
      <inertial>
        <pose>0.002803 -0.005227 0.001089 0 -0 0</pose>
        <mass>1.5871</mass>
        <inertia>
          <ixx>0.001339</ixx>
          <ixy>9e-06</ixy>
          <ixz>1e-05</ixz>
          <iyy>0.001938</iyy>
          <iyz>1.5e-05</iyz>
          <izz>0.001585</izz>
        </inertia>
      </inertial>
      <!--collision name='FL_HIP_collision'>
        <pose>0 0 0 0 -0 0</pose>
        <geometry>
          <mesh>
            <scale>1 1 1</scale>
            <uri>model://PONGBOT_W/meshes/FL_HIP.STL</uri>
          </mesh>
        </geometry>
      </collision-->
      <visual name='FL_HIP_visual'>
        <pose>0 0 0 0 -0 0</pose>
        <geometry>
          <mesh>
            <scale>1 1 1</scale>
            <uri>model://PONGBOT_W/meshes/FL_HIP.STL</uri>
          </mesh>
        </geometry>
        <material>
          <ambient>244 67 54 1</ambient>
          <diffuse>1 1 1 1</diffuse>
          <emissive>0 0 0 1</emissive>
          <specular>0 0 0 0</specular>
        </material>
      </visual>
    </link>
    <joint name='FL_HP_JOINT' type='revolute'>
      <pose relative_to='FL_HIP'>0 0.105 0 0 -0 0</pose>
      <parent>FL_HIP</parent>
      <child>FL_THIGH</child>
      <axis>
        <xyz>0 1 0</xyz>
        <limit>
          <lower>-1e+16</lower>
          <upper>1e+16</upper>
        </limit>
        <dynamics>
          <spring_reference>0</spring_reference>
          <spring_stiffness>0</spring_stiffness>
        </dynamics>
      </axis>
    </joint>
    <link name='FL_THIGH'>
      <pose relative_to='FL_HP_JOINT'>0 0 0 0 -0 0</pose>
      <inertial>
        <pose>0.000189 -0.010257 -0.038433 0 -0 0</pose>
        <mass>3.32</mass>
        <inertia>
          <ixx>0.028079</ixx>
          <ixy>-2.3e-05</ixy>
          <ixz>1.6e-05</ixz>
          <iyy>0.028442</iyy>
          <iyz>-0.001256</iyz>
          <izz>0.003743</izz>
        </inertia>
      </inertial>
      <!--collision name='FL_THIGH_collision'>
        <pose>0 0 0 0 -0 0</pose>
        <geometry>
          <mesh>
            <scale>1 1 1</scale>
            <uri>model://PONGBOT_W/meshes/FL_THIGH.STL</uri>
          </mesh>
        </geometry>
      </collision-->
      <visual name='FL_THIGH_visual'>
        <pose>0 0 0 0 -0 0</pose>
        <geometry>
          <mesh>
            <scale>1 1 1</scale>
            <uri>model://PONGBOT_W/meshes/FL_THIGH.STL</uri>
          </mesh>
        </geometry>
        <material>
          <ambient>244 67 54 1</ambient>
          <diffuse>1 1 1 1</diffuse>
          <emissive>0 0 0 1</emissive>
          <specular>0 0 0 0</specular>
        </material>
      </visual>
    </link>
    <joint name='FL_KN_JOINT' type='revolute'>
      <pose relative_to='FL_THIGH'>0 0 -0.305 0 -0 0</pose>
      <parent>FL_THIGH</parent>
      <child>FL_CALF</child>
      <axis>
        <xyz>0 1 0</xyz>
        <limit>
          <lower>-1e+16</lower>
          <upper>1e+16</upper>
        </limit>
        <dynamics>
          <spring_reference>0</spring_reference>
          <spring_stiffness>0</spring_stiffness>
        </dynamics>
      </axis>
    </joint>
    <link name='FL_CALF'>
      <pose relative_to='FL_KN_JOINT'>0 0 0 0 -0 0</pose>
      <inertial>
        <pose>-0.035789 -0.007154 -0.234470 0 -0 0</pose>
        <mass>1.603349</mass>
        <inertia>
          <ixx>0.027448</ixx>
          <ixy>0.000394</ixy>
          <ixz>0.004712</ixz>
          <iyy>0.028959</iyy>
          <iyz>0.001677</iyz>
          <izz>0.002580</izz>
        </inertia>
      </inertial>
      <!--collision name='FL_CALF_collision'>
        <pose>0 0 0 0 -0 0</pose>
        <geometry>
          <mesh>
            <scale>1 1 1</scale>
            <uri>model://PONGBOT_W/meshes/FL_CALF.STL</uri>
          </mesh>
        </geometry>
      </collision-->
      <visual name='FL_CALF_visual'>
        <pose>0 0 0 0 -0 0</pose>
        <geometry>
          <mesh>
            <scale>1 1 1</scale>
            <uri>model://PONGBOT_W/meshes/FL_CALF.STL</uri>
          </mesh>
        </geometry>
        <material>
          <ambient>0 0 0 1</ambient>
          <diffuse>1 1 1 1</diffuse>
          <emissive>0 0 0 1</emissive>
          <specular>0 0 0 0</specular>
        </material>
      </visual>
    </link>
    <joint name='FL_WHEEL_JOINT' type='revolute'>
      <pose relative_to='FL_CALF'>-0.032441 0 -0.32759 0 -0 0</pose>
      <parent>FL_CALF</parent>
      <child>FL_WHEEL</child>
      <axis>
        <xyz>0 1 0</xyz>
        <limit>
          <lower>-1e+16</lower>
          <upper>1e+16</upper>
        </limit>
        <dynamics>
          <spring_reference>0</spring_reference>
          <spring_stiffness>0</spring_stiffness>
        </dynamics>
      </axis>
    </joint>
    <link name='FL_WHEEL'>
      <pose relative_to='FL_WHEEL_JOINT'>0 0 0 0 -0 0</pose>
      <inertial>
        <pose>0 0.040126 0 0 -0 0</pose>
        <mass>1.01</mass>
        <inertia>
          <ixx>0.003696</ixx>
          <ixy>0</ixy>
          <ixz>0</ixz>
          <iyy>0.007106</iyy>
          <iyz>0</iyz>
          <izz>0.003696</izz>
        </inertia>
      </inertial>
      <collision name='FL_WHEEL_collision'>
        <pose>0 0.041 0 1.57 -0 0</pose>
        <geometry>
          <!--mesh>
            <scale>1 1 1</scale>
            <uri>model://PONGBOT_W/meshes/FL_WHEEL.STL</uri>
          </mesh-->
          <cylinder>
            <radius>0.109</radius>
            <length>0.048</length>  
          </cylinder>
        </geometry>
        <surface>
          <bounce>
            <restitution_coefficient> 0 </restitution_coefficient>
          </bounce>
          <friction>
            <ode>
              <mu>  100  </mu>
              <mu2> 1  </mu2>
            </ode>
          </friction>
          <contact>
            <ode>
      	      <kp>10000000</kp>
              <kd>10000</kd>
<!--               <max_vel>0.1</max_vel>
              <min_depth>0.0001</min_depth> -->
            </ode>
          </contact>
        </surface>      
      </collision>
      <visual name='FL_WHEEL_visual'>
        <pose>0 0 0 0 -0 0</pose>
        <geometry>
          <mesh>
            <scale>1 1 1</scale>
            <uri>model://PONGBOT_W/meshes/FL_WHEEL.STL</uri>
          </mesh>
        </geometry>
        <material>
          <ambient>0 0 0 1</ambient>
          <diffuse>1 1 1 1</diffuse>
          <emissive>0 0 0 1</emissive>
          <specular>0 0 0 0</specular>
        </material>
      </visual>
    </link>
    <joint name='FR_HR_JOINT' type='revolute'>
      <pose relative_to='BODY'>0.31804 -0.1138 0 0 -0 0</pose>
      <parent>BODY</parent>
      <child>FR_HIP</child>
      <axis>
        <xyz>1 0 0</xyz>
        <limit>
          <lower>-1e+16</lower>
          <upper>1e+16</upper>
        </limit>
        <dynamics>
          <spring_reference>0</spring_reference>
          <spring_stiffness>0</spring_stiffness>
        </dynamics>
      </axis>
    </joint>
    <link name='FR_HIP'>
      <pose relative_to='FR_HR_JOINT'>0 0 0 0 -0 0</pose>
      <inertial>
        <pose>0.002897 0.005227 -0.000725 0 -0 0</pose>
        <mass>1.5871</mass>
        <inertia>
          <ixx>0.00134</ixx>
          <ixy>-1.4e-05</ixy>
          <ixz>-1.1e-05</ixz>
          <iyy>0.001938</iyy>
          <iyz>-1e-06</iyz>
          <izz>0.001584</izz>
        </inertia>
      </inertial>
      <!--collision name='FR_HIP_collision'>
        <pose>0 0 0 0 -0 0</pose>
        <geometry>
          <mesh>
            <scale>1 1 1</scale>
            <uri>model://PONGBOT_W/meshes/FR_HIP.STL</uri>
          </mesh>
        </geometry>
      </collision-->
      <visual name='FR_HIP_visual'>
        <pose>0 0 0 0 -0 0</pose>
        <geometry>
          <mesh>
            <scale>1 1 1</scale>
            <uri>model://PONGBOT_W/meshes/FR_HIP.STL</uri>
          </mesh>
        </geometry>
        <material>
          <ambient>244 67 54 1</ambient>
          <diffuse>1 1 1 1</diffuse>
          <emissive>0 0 0 1</emissive>
          <specular>0 0 0 0</specular>
        </material>
      </visual>
    </link>
    <joint name='FR_HP_JOINT' type='revolute'>
      <pose relative_to='FR_HIP'>0 -0.105 0 0 -0 0</pose>
      <parent>FR_HIP</parent>
      <child>FR_THIGH</child>
      <axis>
        <xyz>0 1 0</xyz>
        <limit>
          <lower>-1e+16</lower>
          <upper>1e+16</upper>
        </limit>
        <dynamics>
          <spring_reference>0</spring_reference>
          <spring_stiffness>0</spring_stiffness>
        </dynamics>
      </axis>
    </joint>
    <link name='FR_THIGH'>
      <pose relative_to='FR_HP_JOINT'>0 0 0 0 -0 0</pose>
      <inertial>
        <pose>-0.000189 0.010257 -0.038433 0 -0 0</pose>
        <mass>3.32</mass>
        <inertia>
          <ixx>0.028079</ixx>
          <ixy>-2.3e-05</ixy>
          <ixz>-1.6e-05</ixz>
          <iyy>0.028442</iyy>
          <iyz>0.001256</iyz>
          <izz>0.003743</izz>
        </inertia>
      </inertial>
      <!--collision name='FR_THIGH_collision'>
        <pose>0 0 0 0 -0 0</pose>
        <geometry>
          <mesh>
            <scale>1 1 1</scale>
            <uri>model://PONGBOT_W/meshes/FR_THIGH.STL</uri>
          </mesh>
        </geometry>
      </collision-->
      <visual name='FR_THIGH_visual'>
        <pose>0 0 0 0 -0 0</pose>
        <geometry>
          <mesh>
            <scale>1 1 1</scale>
            <uri>model://PONGBOT_W/meshes/FR_THIGH.STL</uri>
          </mesh>
        </geometry>
        <material>
          <ambient>244 67 54 1</ambient>
          <diffuse>1 1 1 1</diffuse>
          <emissive>0 0 0 1</emissive>
          <specular>0 0 0 0</specular>
        </material>
      </visual>
    </link>
    <joint name='FR_KN_JOINT' type='revolute'>
      <pose relative_to='FR_THIGH'>0 0 -0.305 0 -0 0</pose>
      <parent>FR_THIGH</parent>
      <child>FR_CALF</child>
      <axis>
        <xyz>0 1 0</xyz>
        <limit>
          <lower>-1e+16</lower>
          <upper>1e+16</upper>
        </limit>
        <dynamics>
          <spring_reference>0</spring_reference>
          <spring_stiffness>0</spring_stiffness>
        </dynamics>
      </axis>
    </joint>
    <link name='FR_CALF'>
      <pose relative_to='FR_KN_JOINT'>0 0 0 0 -0 0</pose>
      <inertial>
        <pose>-0.017892 0.004092 -0.236398 0 -0 0</pose>
        <mass>1.603349</mass>
        <inertia>
          <ixx>0.027926</ixx>
          <ixy>-0.000177</ixy>
          <ixz>0.002307</ixz>
          <iyy>0.028625</iyy>
          <iyz>-0.001273</iyz>
          <izz>0.001669</izz>
        </inertia>
      </inertial>
      <!--collision name='FR_CALF_collision'>
        <pose>0 0 0 0 -0 0</pose>
        <geometry>
          <mesh>
            <scale>1 1 1</scale>
            <uri>model://PONGBOT_W/meshes/FR_CALF.STL</uri>
          </mesh>
        </geometry>
      </collision-->
      <visual name='FR_CALF_visual'>
        <pose>0 0 0 0 -0 0</pose>
        <geometry>
          <mesh>
            <scale>1 1 1</scale>
            <uri>model://PONGBOT_W/meshes/FR_CALF.STL</uri>
          </mesh>
        </geometry>
        <material>
          <ambient>0 0 0 1</ambient>
          <diffuse>1 1 1 1</diffuse>
          <emissive>0 0 0 1</emissive>
          <specular>0 0 0 0</specular>
        </material>
      </visual>
    </link>
    <joint name='FR_WHEEL_JOINT' type='revolute'>
      <pose relative_to='FR_CALF'>-0.032441 0 -0.32759 0 -0 0</pose>
      <parent>FR_CALF</parent>
      <child>FR_WHEEL</child>
      <axis>
        <xyz>0 1 0</xyz>
        <limit>
          <lower>-1e+16</lower>
          <upper>1e+16</upper>
        </limit>
        <dynamics>
          <spring_reference>0</spring_reference>
          <spring_stiffness>0</spring_stiffness>
        </dynamics>
      </axis>
    </joint>
    <link name='FR_WHEEL'>
      <pose relative_to='FR_WHEEL_JOINT'>0 0 0 0 -0 0</pose>
      <inertial>
        <pose>0 -0.040126 0 0 -0 0</pose>
        <mass>1.01</mass>
        <inertia>
          <ixx>0.003696</ixx>
          <ixy>0</ixy>
          <ixz>0</ixz>
          <iyy>0.007106</iyy>
          <iyz>0</iyz>
          <izz>0.003696</izz>
        </inertia>
      </inertial>
      <collision name='FR_WHEEL_collision'>
        <pose>0 -0.041 0 1.57 -0 0</pose>
        <geometry>
          <!--mesh>
            <scale>1 1 1</scale>
            <uri>model://PONGBOT_W/meshes/FR_WHEEL.STL</uri>
          </mesh-->
          <cylinder>
            <radius>0.109</radius>
            <length>0.048</length>  
          </cylinder>
        </geometry>
                <surface>
          <bounce>
            <restitution_coefficient> 0 </restitution_coefficient>
          </bounce>
          <friction>
            <ode>
              <mu>  100  </mu>
              <mu2> 1  </mu2>
            </ode>
          </friction>
          <contact>
            <ode>
      	      <kp>10000000</kp>
              <kd>10000</kd>
<!--               <max_vel>0.1</max_vel>
              <min_depth>0.0001</min_depth> -->
            </ode>
          </contact>
        </surface>
      </collision>
      <visual name='FR_WHEEL_visual'>
        <pose>0 0 0 0 -0 0</pose>
        <geometry>
          <mesh>
            <scale>1 1 1</scale>
            <uri>model://PONGBOT_W/meshes/FR_WHEEL.STL</uri>
          </mesh>
        </geometry>
        <material>
          <ambient>0 0 0 1</ambient>
          <diffuse>1 1 1 1</diffuse>
          <emissive>0 0 0 1</emissive>
          <specular>0 0 0 0</specular>
        </material>
      </visual>
    </link>
    <joint name='RL_HR_JOINT' type='revolute'>
      <pose relative_to='BODY'>-0.31804 0.1138 0 0 -0 0</pose>
      <parent>BODY</parent>
      <child>RL_HIP</child>
      <axis>
        <xyz>1 0 0</xyz>
        <limit>
          <lower>-1e+16</lower>
          <upper>1e+16</upper>
        </limit>
        <dynamics>
          <spring_reference>0</spring_reference>
          <spring_stiffness>0</spring_stiffness>
        </dynamics>
      </axis>
    </joint>
    <link name='RL_HIP'>
      <pose relative_to='RL_HR_JOINT'>0 0 0 0 -0 0</pose>
      <inertial>
        <pose>-0.002897 -0.005227 -0.000725 0 -0 0</pose>
        <mass>1.5871</mass>
        <inertia>
          <ixx>0.00134</ixx>
          <ixy>-1.4e-05</ixy>
          <ixz>1.1e-05</ixz>
          <iyy>0.001938</iyy>
          <iyz>1e-06</iyz>
          <izz>0.001584</izz>
        </inertia>
      </inertial>
      <!--collision name='RL_HIP_collision'>
        <pose>0 0 0 0 -0 0</pose>
        <geometry>
          <mesh>
            <scale>1 1 1</scale>
            <uri>model://PONGBOT_W/meshes/RL_HIP.STL</uri>
          </mesh>
        </geometry>
      </collision-->
      <visual name='RL_HIP_visual'>
        <pose>0 0 0 0 -0 0</pose>
        <geometry>
          <mesh>
            <scale>1 1 1</scale>
            <uri>model://PONGBOT_W/meshes/RL_HIP.STL</uri>
          </mesh>
        </geometry>
      </visual>
    </link>
    <joint name='RL_HP_JOINT' type='revolute'>
      <pose relative_to='RL_HIP'>0 0.105 0 0 -0 0</pose>
      <parent>RL_HIP</parent>
      <child>RL_THIGH</child>
      <axis>
        <xyz>0 1 0</xyz>
        <limit>
          <lower>-1e+16</lower>
          <upper>1e+16</upper>
        </limit>
        <dynamics>
          <spring_reference>0</spring_reference>
          <spring_stiffness>0</spring_stiffness>
        </dynamics>
      </axis>
    </joint>
    <link name='RL_THIGH'>
      <pose relative_to='RL_HP_JOINT'>0 0 0 0 -0 0</pose>
      <inertial>
        <pose>0.000189 -0.010257 -0.038433 0 -0 0</pose>
        <mass>3.32</mass>
        <inertia>
          <ixx>0.028079</ixx>
          <ixy>-2.3e-05</ixy>
          <ixz>1.6e-05</ixz>
          <iyy>0.028442</iyy>
          <iyz>-0.001256</iyz>
          <izz>0.003743</izz>
        </inertia>
      </inertial>
      <!--collision name='RL_THIGH_collision'>
        <pose>0 0 0 0 -0 0</pose>
        <geometry>
          <mesh>
            <scale>1 1 1</scale>
            <uri>model://PONGBOT_W/meshes/RL_THIGH.STL</uri>
          </mesh>
        </geometry>
      </collision-->
      <visual name='RL_THIGH_visual'>
        <pose>0 0 0 0 -0 0</pose>
        <geometry>
          <mesh>
            <scale>1 1 1</scale>
            <uri>model://PONGBOT_W/meshes/RL_THIGH.STL</uri>
          </mesh>
        </geometry>
        <material>
          <ambient>244 67 54 1</ambient>
          <diffuse>1 1 1 1</diffuse>
          <emissive>0 0 0 1</emissive>
          <specular>0 0 0 0</specular>
        </material>
      </visual>
    </link>
    <joint name='RL_KN_JOINT' type='revolute'>
      <pose relative_to='RL_THIGH'>0 0 -0.305 0 -0 0</pose>
      <parent>RL_THIGH</parent>
      <child>RL_CALF</child>
      <axis>
        <xyz>0 1 0</xyz>
        <limit>
          <lower>-1e+16</lower>
          <upper>1e+16</upper>
        </limit>
        <dynamics>
          <spring_reference>0</spring_reference>
          <spring_stiffness>0</spring_stiffness>
        </dynamics>
      </axis>
    </joint>
    <link name='RL_CALF'>
      <pose relative_to='RL_KN_JOINT'>0 0 0 0 -0 0</pose>
      <inertial>
        <pose>-0.035789 -0.007154 -0.234470 0 -0 0</pose>
        <mass>1.603349</mass>
        <inertia>
          <ixx>0.027448</ixx>
          <ixy>0.000394</ixy>
          <ixz>0.004712</ixz>
          <iyy>0.028959</iyy>
          <iyz>0.001677</iyz>
          <izz>0.002580"</izz>
        </inertia>
      </inertial>
      <!--collision name='RL_CALF_collision'>
        <pose>0 0 0 0 -0 0</pose>
        <geometry>
          <mesh>
            <scale>1 1 1</scale>
            <uri>model://PONGBOT_W/meshes/RL_CALF.STL</uri>
          </mesh>
        </geometry>
      </collision-->
      <visual name='RL_CALF_visual'>
        <pose>0 0 0 0 -0 0</pose>
        <geometry>
          <mesh>
            <scale>1 1 1</scale>
            <uri>model://PONGBOT_W/meshes/RL_CALF.STL</uri>
          </mesh>
        </geometry>
        <material>
          <ambient>0 0 0 1</ambient>
          <diffuse>1 1 1 1</diffuse>
          <emissive>0 0 0 1</emissive>
          <specular>0 0 0 0</specular>
        </material>
      </visual>
    </link>
    <joint name='RL_WHEEL_JOINT' type='revolute'>
      <pose relative_to='RL_CALF'>-0.032441 0 -0.32759 0 -0 0</pose>
      <parent>RL_CALF</parent>
      <child>RL_WHEEL</child>
      <axis>
        <xyz>0 1 0</xyz>
        <limit>
          <lower>-1e+16</lower>
          <upper>1e+16</upper>
        </limit>
        <dynamics>
          <spring_reference>0</spring_reference>
          <spring_stiffness>0</spring_stiffness>
        </dynamics>
      </axis>
    </joint>
    <link name='RL_WHEEL'>
      <pose relative_to='RL_WHEEL_JOINT'>0 0 0 0 -0 0</pose>
      <inertial>
        <pose>0 0.040126 0 0 -0 0</pose>
        <mass>1.01</mass>
        <inertia>
          <ixx>0.003696</ixx>
          <ixy>0</ixy>
          <ixz>0</ixz>
          <iyy>0.007106</iyy>
          <iyz>0</iyz>
          <izz>0.003696</izz>
        </inertia>
      </inertial>
      <collision name='RL_WHEEL_collision'>
        <pose>0 0.041 0 1.57 -0 0</pose>
        <geometry>
          <!--mesh>
            <scale>1 1 1</scale>
            <uri>model://PONGBOT_W/meshes/RL_WHEEL.STL</uri>
          </mesh-->
          <cylinder>
            <radius>0.109</radius>
            <length>0.048</length>  
          </cylinder>
        </geometry>
        <surface>
          <bounce>
            <restitution_coefficient> 0 </restitution_coefficient>
          </bounce>
          <friction>
            <ode>
              <mu>  100  </mu>
              <mu2> 1  </mu2>
            </ode>
          </friction>
          <contact>
            <ode>
      	      <kp>10000000</kp>
              <kd>10000</kd>
<!--               <max_vel>0.1</max_vel>
              <min_depth>0.0001</min_depth> -->
            </ode>
          </contact>
        </surface>
      </collision>
      <visual name='RL_WHEEL_visual'>
        <pose>0 0 0 0 -0 0</pose>
        <geometry>
          <mesh>
            <scale>1 1 1</scale>
            <uri>model://PONGBOT_W/meshes/RL_WHEEL.STL</uri>
          </mesh>
        </geometry>
        <material>
          <ambient>0 0 0 1</ambient>
          <diffuse>1 1 1 1</diffuse>
          <emissive>0 0 0 1</emissive>
          <specular>0 0 0 0</specular>
        </material>
      </visual>
    </link>
    <joint name='RR_HR_JOINT' type='revolute'>
      <pose relative_to='BODY'>-0.31804 -0.1138 0 0 -0 0</pose>
      <parent>BODY</parent>
      <child>RR_HIP</child>
      <axis>
        <xyz>1 0 0</xyz>
        <limit>
          <lower>-1e+16</lower>
          <upper>1e+16</upper>
        </limit>
        <dynamics>
          <spring_reference>0</spring_reference>
          <spring_stiffness>0</spring_stiffness>
        </dynamics>
      </axis>
    </joint>
    <link name='RR_HIP'>
      <pose relative_to='RR_HR_JOINT'>0 0 0 0 -0 0</pose>
      <inertial>
        <pose>-0.0028 0.005227 0.001089 0 -0 0</pose>
        <mass>1.5871</mass>
        <inertia>
          <ixx>0.001339</ixx>
          <ixy>9e-06</ixy>
          <ixz>-1e-05</ixz>
          <iyy>0.001937</iyy>
          <iyz>-1.5e-05</iyz>
          <izz>0.001585</izz>
        </inertia>
      </inertial>
      <!--collision name='RR_HIP_collision'>
        <pose>0 0 0 0 -0 0</pose>
        <geometry>
          <mesh>
            <scale>1 1 1</scale>
            <uri>model://PONGBOT_W/meshes/RR_HIP.STL</uri>
          </mesh>
        </geometry>
      </collision-->
      <visual name='RR_HIP_visual'>
        <pose>0 0 0 0 -0 0</pose>
        <geometry>
          <mesh>
            <scale>1 1 1</scale>
            <uri>model://PONGBOT_W/meshes/RR_HIP.STL</uri>
          </mesh>
        </geometry>
        <material>
          <ambient>244 67 54 1</ambient>
          <diffuse>1 1 1 1</diffuse>
          <emissive>0 0 0 1</emissive>
          <specular>0 0 0 0</specular>
        </material>
      </visual>
    </link>
    <joint name='RR_HP_JOINT' type='revolute'>
      <pose relative_to='RR_HIP'>0 -0.105 0 0 -0 0</pose>
      <parent>RR_HIP</parent>
      <child>RR_THIGH</child>
      <axis>
        <xyz>0 1 0</xyz>
        <limit>
          <lower>-1e+16</lower>
          <upper>1e+16</upper>
        </limit>
        <dynamics>
          <spring_reference>0</spring_reference>
          <spring_stiffness>0</spring_stiffness>
        </dynamics>
      </axis>
    </joint>
    <link name='RR_THIGH'>
      <pose relative_to='RR_HP_JOINT'>0 0 0 0 -0 0</pose>
      <inertial>
        <pose>-0.000189 0.010257 -0.038433 0 -0 0</pose>
        <mass>3.32</mass>
        <inertia>
          <ixx>0.028079</ixx>
          <ixy>-2.3e-05</ixy>
          <ixz>-1.6e-05</ixz>
          <iyy>0.028442</iyy>
          <iyz>0.001256</iyz>
          <izz>0.003743</izz>
        </inertia>
      </inertial>
      <!--collision name='RR_THIGH_collision'>
        <pose>0 0 0 0 -0 0</pose>
        <geometry>
          <mesh>
            <scale>1 1 1</scale>
            <uri>model://PONGBOT_W/meshes/RR_THIGH.STL</uri>
          </mesh>
        </geometry>
      </collision-->
      <visual name='RR_THIGH_visual'>
        <pose>0 0 0 0 -0 0</pose>
        <geometry>
          <mesh>
            <scale>1 1 1</scale>
            <uri>model://PONGBOT_W/meshes/RR_THIGH.STL</uri>
          </mesh>
        </geometry>
        <material>
          <ambient>244 67 54 1</ambient>
          <diffuse>1 1 1 1</diffuse>
          <emissive>0 0 0 1</emissive>
          <specular>0 0 0 0</specular>
        </material> 
      </visual>
    </link>
    <joint name='RR_KN_JOINT' type='revolute'>
      <pose relative_to='RR_THIGH'>0 0 -0.305 0 -0 0</pose>
      <parent>RR_THIGH</parent>
      <child>RR_CALF</child>
      <axis>
        <xyz>0 1 0</xyz>
        <limit>
          <lower>-1e+16</lower>
          <upper>1e+16</upper>
        </limit>
        <dynamics>
          <spring_reference>0</spring_reference>
          <spring_stiffness>0</spring_stiffness>
        </dynamics>
      </axis>
    </joint>
    <link name='RR_CALF'>
      <pose relative_to='RR_KN_JOINT'>0 0 0 0 -0 0</pose>
      <inertial>
        <pose>-0.017892 0.0049092 -0.23698 0 -0 0</pose>
        <mass>1.603349</mass>
        <inertia>
          <ixx>0.027926</ixx>
          <ixy>-0.000177</ixy>
          <ixz>0.002307</ixz>
          <iyy>0.028625</iyy>
          <iyz>-0.001273</iyz>
          <izz>0.001669</izz>
        </inertia>
      </inertial>
      <!--collision name='RR_CALF_collision'>
        <pose>0 0 0 0 -0 0</pose>
        <geometry>
          <mesh>
            <scale>1 1 1</scale>
            <uri>model://PONGBOT_W/meshes/RR_CALF.STL</uri>
          </mesh>
        </geometry>
      </collision-->
      <visual name='RR_CALF_visual'>
        <pose>0 0 0 0 -0 0</pose>
        <geometry>
          <mesh>
            <scale>1 1 1</scale>
            <uri>model://PONGBOT_W/meshes/RR_CALF.STL</uri>
          </mesh>
        </geometry>
        <material>
          <ambient>0 0 0 1</ambient>
          <diffuse>1 1 1 1</diffuse>
          <emissive>0 0 0 1</emissive>
          <specular>0 0 0 0</specular>
        </material>
      </visual>
    </link>
    <joint name='RR_WHEEL_JOINT' type='revolute'>
      <pose relative_to='RR_CALF'>-0.032441 0 -0.32759 0 -0 0</pose>
      <parent>RR_CALF</parent>
      <child>RR_WHEEL</child>
      <axis>
        <xyz>0 1 0</xyz>
        <limit>
          <lower>-1e+16</lower>
          <upper>1e+16</upper>
        </limit>
        <dynamics>
          <spring_reference>0</spring_reference>
          <spring_stiffness>0</spring_stiffness>
        </dynamics>
      </axis>
    </joint>
    <link name='RR_WHEEL'>
      <pose relative_to='RR_WHEEL_JOINT'>0 0 0 0 -0 0</pose>
      <inertial>
        <pose>0 -0.040126 0 0 -0 0</pose>
        <mass>1.01</mass>
        <inertia>
          <ixx>0.003696</ixx>
          <ixy>0</ixy>
          <ixz>0</ixz>
          <iyy>0.007106</iyy>
          <iyz>0</iyz>
          <izz>0.003696</izz>
        </inertia>
      </inertial>
      <collision name='RR_WHEEL_collision'>
        <pose>0 -0.041 0 1.57 -0 0</pose>
        <geometry>
          <!--mesh>
            <scale>1 1 1</scale>
            <uri>model://PONGBOT_W/meshes/RR_WHEEL.STL</uri>
          </mesh-->
          <cylinder>
            <radius>0.109</radius>
            <length>0.048</length>  
          </cylinder>
        </geometry>
        <surface>
          <bounce>
            <restitution_coefficient> 0 </restitution_coefficient>
          </bounce>
          <friction>
            <ode>
              <mu>  100  </mu>
              <mu2> 1  </mu2>
            </ode>
          </friction>
          <contact>
            <ode>
      	      <kp>10000000</kp>
              <kd>10000</kd>
<!--               <max_vel>0.1</max_vel>
              <min_depth>0.0001</min_depth> -->
            </ode>
          </contact>
        </surface>
      </collision>
      <visual name='RR_WHEEL_visual'>
        <pose>0 0 0 0 -0 0</pose>
        <geometry>
          <mesh>
            <scale>1 1 1</scale>
            <uri>model://PONGBOT_W/meshes/RR_WHEEL.STL</uri>
          </mesh>
        </geometry>
        <material>
          <ambient>0 0 0 1</ambient>
          <diffuse>1 1 1 1</diffuse>
          <emissive>0 0 0 1</emissive>
          <specular>0 0 0 0</specular>
        </material>
      </visual>
    </link>
  </model>
</sdf>
